Workbook

Sheet Population
A1: Philippines | B1: 115377992 | F1: source | G1: https://psa.gov.ph/system/files/phcd/2022-12/Cities%2520and%2520Municipalities%2520Population%2520Projections_2015CBPP_Phils.pdf
A2: NCR | B2: 14521657 | F2: regions VI and VII include NIR (occidental and oriental, respectively
A3: CAR | B3: 1874281 | F3: these regions will not be processed due to difference in reporting of regions
A4: Region I | B4: 5458063
A5: Region II | B5: 3817144
A6: Region III | B6: 13239670
A7: Region IV-A | B7: 17477569
A8: Region IV-B | B8: 3342831
A9: Region V | B9: 6397690
A10: Region VI | B10: 8201699
A11: Region VII | B11: 8391707
A12: Region VIII | B12: 5049226
A13: Region IX | B13: 3901529
A14: Region X | B14: 5273604
A15: Region XI | B15: 5691183
... A18: BARMM | B18: 4635519

Sheet Diseases
A1: Rank | B1: Diseases | C1: Month | D1: Area | E1: Gender | F1: Cases | G1: Population | H1: Incidence Rate (per 100k)
A2: 1 | B2: Respiratory Diseases | C2: January | D2: National Capital Region | E2: Male | F2: 4447 | G2: 14521657 | H2: {=F2/G2*100000} -> 30.623227
A3: 2 | B3: Cardiovascular Diseases | C3: January | D3: National Capital Region | E3: Male | F3: 3297 | G3: 14521657 | H3: {=F3/G3*100000} -> 22.704021
A4: 3 | B4: Respiratory Diseases | C4: January | D4: National Capital Region | E4: Male | F4: 3344 | G4: 14521657 | H4: {=F4/G4*100000} -> 23.027675
A5: 4 | B5: Injuries & External Causes | C5: January | D5: National Capital Region | E5: Male | F5: 2842 | G5: 14521657 | H5: {=F5/G5*100000} -> 19.570769
A6: 5 | B6: Respiratory Diseases | C6: January | D6: National Capital Region | E6: Male | F6: 1360 | G6: 14521657 | H6: {=F6/G6*100000} -> 9.3653224
A7: 6 | B7: Cardiovascular Diseases | C7: January | D7: National Capital Region | E7: Male | F7: 767 | G7: 14521657 | H7: {=F7/G7*100000} -> 5.2817664
A8: 7 | B8: Skin & Soft Tissue Diseases | C8: January | D8: National Capital Region | E8: Male | F8: 733 | G8: 14521657 | H8: {=F8/G8*100000} -> 5.0476333
A9: 8 | B9: Respiratory Diseases | C9: January | D9: National Capital Region | E9: Male | F9: 757 | G9: 14521657 | H9: {=F9/G9*100000} -> 5.2129037
A10: 9 | B10: Respiratory Diseases | C10: January | D10: National Capital Region | E10: Male | F10: 727 | G10: 14521657 | H10: {=F10/G10*100000} -> 5.0063157
A11: 10 | B11: Digestive & Metabolic Disorders | C11: January | D11: National Capital Region | E11: Male | F11: 644 | G11: 14521657 | H11: {=F11/G11*100000} -> 4.4347556
A12: 1 | B12: Respiratory Diseases | C12: January | D12: Cordillera Administrative Region | E12: Male | F12: 7737 | G12: 1874281 | H12: {=F12/G12*100000} -> 412.79829
A13: 2 | B13: Cardiovascular Diseases | C13: January | D13: Cordillera Administrative Region | E13: Male | F13: 3088 | G13: 1874281 | H13: {=F13/G13*100000} -> 164.75651
... A71: 10 | B71: Genitourinary & Reproductive Health | C71: January | D71: Mimaropa | E71: Male | F71: 104 | G71: 3342831 | H71: {=F71/G71*100000} -> 3.1111354
A72: 1 | B72: No reported data | C72: January | D72: Bicol | E72: Male | F72: 0 | G72: 6397690 | H72: N/A
A73: 2 | B73: No reported data | C73: January | D73: Bicol | E73: Male | F73: 0 | G73: 6397690 | H73: N/A
A74: 3 | B74: No reported data | C74: January | D74: Bicol | E74: Male | F74: 0 | G74: 6397690 | H74: N/A
A75: 4 | B75: No reported data | C75: January | D75: Bicol | E75: Male | F75: 0 | G75: 6397690 | H75: N/A
A76: 5 | B76: No reported data | C76: January | D76: Bicol | E76: Male | F76: 0 | G76: 6397690 | H76: N/A
A77: 6 | B77: No reported data | C77: January | D77: Bicol | E77: Male | F77: 0 | G77: 6397690 | H77: N/A
A78: 7 | B78: No reported data | C78: January | D78: Bicol | E78: Male | F78: 0 | G78: 6397690 | H78: N/A
A79: 8 | B79: No reported data | C79: January | D79: Bicol | E79: Male | F79: 0 | G79: 6397690 | H79: N/A
A80: 9 | B80: No reported data | C80: January | D80: Bicol | E80: Male | F80: 0 | G80: 6397690 | H80: N/A
A81: 10 | B81: No reported data | C81: January | D81: Bicol | E81: Male | F81: 0 | G81: 6397690 | H81: N/A
A82: 1 | B82: Respiratory Diseases | C82: January | D82: Western Visayas | E82: Male | F82: 1084
A83: 2 | B83: Cardiovascular Diseases | C83: January | D83: Western Visayas | E83: Male | F83: 868
A84: 3 | B84: Respiratory Diseases | C84: January | D84: Western Visayas | E84: Male | F84: 839
A85: 4 | B85: Injuries & External Causes | C85: January | D85: Western Visayas | E85: Male | F85: 534
A86: 5 | B86: Genitourinary & Reproductive Health | C86: January | D86: Western Visayas | E86: Male | F86: 209
A87: 6 | B87: Respiratory Diseases | C87: January | D87: Western Visayas | E87: Male | F87: 267
A88: 7 | B88: Respiratory Diseases | C88: January | D88: Western Visayas | E88: Male | F88: 174
A89: 8 | B89: Skin & Soft Tissue Diseases | C89: January | D89: Western Visayas | E89: Male | F89: 50
A90: 9 | B90: Respiratory Diseases | C90: January | D90: Western Visayas | E90: Male | F90: 39
A91: 10 | B91: Digestive & Metabolic Disorders | C91: January | D91: Western Visayas | E91: Male | F91: 29
A92: 1 | B92: Respiratory Diseases | C92: January | D92: Central Visayas | E92: Male | F92: 5354
A93: 2 | B93: Injuries & External Causes | C93: January | D93: Central Visayas | E93: Male | F93: 5528
... A101: 10 | B101: Symptoms & Other Findings | C101: January | D101: Central Visayas | E101: Male | F101: 627
A102: 1 | B102: Symptoms & Other Findings | C102: January | D102: Eastern Visayas | E102: Male | F102: 1156 | G102: 5049226 | H102: {=F102/G102*100000} -> 22.894598
A103: 2 | B103: Respiratory Diseases | C103: January | D103: Eastern Visayas | E103: Male | F103: 278 | G103: 5049226 | H103: {=F103/G103*100000} -> 5.5057944
A104: 3 | B104: Infectious & Parasitic Diseases | C104: January | D104: Eastern Visayas | E104: Male | F104: 127 | G104: 5049226 | H104: {=F104/G104*100000} -> 2.515237
...

Sheet Total Cases
A1: Diseases | B1: Month | C1: Area | D1: Total Cases (M+F) | E1: Population | F1: Incidence Rate (per 100k)
A2: Respiratory Diseases | B2: January | C2: National Capital Region | D2: {=_xlfn.SUMIFS('Diseases'!F2:F4303,'Diseases'!B2:B4303,A2,'Diseases'!C2:C4303,B2,'Diseases'!D2:D4303,C2)} -> 22804 | E2: {=_xlfn.IFERROR(IF(INDEX('Diseases'!G2:G4303,MATCH(C2,'Diseases'!D2:D4303,0))="","",INDEX('Diseases'!G2:G4303,MATCH(C2,'Diseases'!D2:D4303,0))),"")} -> 14521657 | F2: {=_xlfn.IFERROR(IF(E2="","",D2/E2*100000),"")} -> 157.03442
A3: Cardiovascular Diseases | B3: January | C3: National Capital Region | D3: {=_xlfn.SUMIFS('Diseases'!F2:F4303,'Diseases'!B2:B4303,A3,'Diseases'!C2:C4303,B3,'Diseases'!D2:D4303,C3)} -> 9819 | E3: {=_xlfn.IFERROR(IF(INDEX('Diseases'!G2:G4303,MATCH(C3,'Diseases'!D2:D4303,0))="","",INDEX('Diseases'!G2:G4303,MATCH(C3,'Diseases'!D2:D4303,0))),"")} -> 14521657 | F3: {=_xlfn.IFERROR(IF(E3="","",D3/E3*100000),"")} -> 67.616251
A4: Injuries & External Causes | B4: January | C4: National Capital Region | D4: {=_xlfn.SUMIFS('Diseases'!F2:F4303,'Diseases'!B2:B4303,A4,'Diseases'!C2:C4303,B4,'Diseases'!D2:D4303,C4)} -> 6497 | E4: {=_xlfn.IFERROR(IF(INDEX('Diseases'!G2:G4303,MATCH(C4,'Diseases'!D2:D4303,0))="","",INDEX('Diseases'!G2:G4303,MATCH(C4,'Diseases'!D2:D4303,0))),"")} -> 14521657 | F4: {=_xlfn.IFERROR(IF(E4="","",D4/E4*100000),"")} -> 44.740073
A5: Skin & Soft Tissue Diseases | B5: January | C5: National Capital Region | D5: {=_xlfn.SUMIFS('Diseases'!F2:F4303,'Diseases'!B2:B4303,A5,'Diseases'!C2:C4303,B5,'Diseases'!D2:D4303,C5)} -> 1534 | E5: {=_xlfn.IFERROR(IF(INDEX('Diseases'!G2:G4303,MATCH(C5,'Diseases'!D2:D4303,0))="","",INDEX('Diseases'!G2:G4303,MATCH(C5,'Diseases'!D2:D4303,0))),"")} -> 14521657 | F5: {=_xlfn.IFERROR(IF(E5="","",D5/E5*100000),"")} -> 10.563533
A6: Digestive & Metabolic Disorders | B6: January | C6: National Capital Region | D6: {=_xlfn.SUMIFS('Diseases'!F2:F4303,'Diseases'!B2:B4303,A6,'Diseases'!C2:C4303,B6,'Diseases'!D2:D4303,C6)} -> 1422 | E6: {=_xlfn.IFERROR(IF(INDEX('Diseases'!G2:G4303,MATCH(C6,'Diseases'!D2:D4303,0))="","",INDEX('Diseases'!G2:G4303,MATCH(C6,'Diseases'!D2:D4303,0))),"")} -> 14521657 | F6: {=_xlfn.IFERROR(IF(E6="","",D6/E6*100000),"")} -> 9.792271
A7: Respiratory Diseases | B7: February | C7: National Capital Region | D7: {=_xlfn.SUMIFS('Diseases'!F2:F4303,'Diseases'!B2:B4303,A7,'Diseases'!C2:C4303,B7,'Diseases'!D2:D4303,C7)} -> 22824 | E7: {=_xlfn.IFERROR(IF(INDEX('Diseases'!G2:G4303,MATCH(C7,'Diseases'!D2:D4303,0))="","",INDEX('Diseases'!G2:G4303,MATCH(C7,'Diseases'!D2:D4303,0))),"")} -> 14521657 | F7: {=_xlfn.IFERROR(IF(E7="","",D7/E7*100000),"")} -> 157.17215
A8: Injuries & External Causes | B8: February | C8: National Capital Region | D8: {=_xlfn.SUMIFS('Diseases'!F2:F4303,'Diseases'!B2:B4303,A8,'Diseases'!C2:C4303,B8,'Diseases'!D2:D4303,C8)} -> 10177 | E8: {=_xlfn.IFERROR(IF(INDEX('Diseases'!G2:G4303,MATCH(C8,'Diseases'!D2:D4303,0))="","",INDEX('Diseases'!G2:G4303,MATCH(C8,'Diseases'!D2:D4303,0))),"")} -> 14521657 | F8: {=_xlfn.IFERROR(IF(E8="","",D8/E8*100000),"")} -> 70.081534
A9: Cardiovascular Diseases | B9: February | C9: National Capital Region | D9: {=_xlfn.SUMIFS('Diseases'!F2:F4303,'Diseases'!B2:B4303,A9,'Diseases'!C2:C4303,B9,'Diseases'!D2:D4303,C9)} -> 7527 | E9: {=_xlfn.IFERROR(IF(INDEX('Diseases'!G2:G4303,MATCH(C9,'Diseases'!D2:D4303,0))="","",INDEX('Diseases'!G2:G4303,MATCH(C9,'Diseases'!D2:D4303,0))),"")} -> 14521657 | F9: {=_xlfn.IFERROR(IF(E9="","",D9/E9*100000),"")} -> 51.832928
A10: Symptoms & Other Findings | B10: February | C10: National Capital Region | D10: {=_xlfn.SUMIFS('Diseases'!F2:F4303,'Diseases'!B2:B4303,A10,'Diseases'!C2:C4303,B10,'Diseases'!D2:D4303,C10)} -> 5642 | E10: {=_xlfn.IFERROR(IF(INDEX('Diseases'!G2:G4303,MATCH(C10,'Diseases'!D2:D4303,0))="","",INDEX('Diseases'!G2:G4303,MATCH(C10,'Diseases'!D2:D4303,0))),"")} -> 14521657 | F10: {=_xlfn.IFERROR(IF(E10="","",D10/E10*100000),"")} -> 38.852316
A11: Digestive & Metabolic Disorders | B11: February | C11: National Capital Region | D11: {=_xlfn.SUMIFS('Diseases'!F2:F4303,'Diseases'!B2:B4303,A11,'Diseases'!C2:C4303,B11,'Diseases'!D2:D4303,C11)} -> 4161 | E11: {=_xlfn.IFERROR(IF(INDEX('Diseases'!G2:G4303,MATCH(C11,'Diseases'!D2:D4303,0))="","",INDEX('Diseases'!G2:G4303,MATCH(C11,'Diseases'!D2:D4303,0))),"")} -> 14521657 | F11: {=_xlfn.IFERROR(IF(E11="","",D11/E11*100000),"")} -> 28.653755
A12: Genitourinary & Reproductive Health | B12: February | C12: National Capital Region | D12: {=_xlfn.SUMIFS('Diseases'!F2:F4303,'Diseases'!B2:B4303,A12,'Diseases'!C2:C4303,B12,'Diseases'!D2:D4303,C12)} -> 1895 | E12: {=_xlfn.IFERROR(IF(INDEX('Diseases'!G2:G4303,MATCH(C12,'Diseases'!D2:D4303,0))="","",INDEX('Diseases'!G2:G4303,MATCH(C12,'Diseases'!D2:D4303,0))),"")} -> 14521657 | F12: {=_xlfn.IFERROR(IF(E12="","",D12/E12*100000),"")} -> 13.049475
A13: Respiratory Diseases | B13: March | C13: National Capital Region | D13: {=_xlfn.SUMIFS('Diseases'!F2:F4303,'Diseases'!B2:B4303,A13,'Diseases'!C2:C4303,B13,'Diseases'!D2:D4303,C13)} -> 22556 | E13: {=_xlfn.IFERROR(IF(INDEX('Diseases'!G2:G4303,MATCH(C13,'Diseases'!D2:D4303,0))="","",INDEX('Diseases'!G2:G4303,MATCH(C13,'Diseases'!D2:D4303,0))),"")} -> 14521657 | F13: {=_xlfn.IFERROR(IF(E13="","",D13/E13*100000),"")} -> 155.32663
A14: Cardiovascular Diseases | B14: March | C14: National Capital Region | D14: {=_xlfn.SUMIFS('Diseases'!F2:F4303,'Diseases'!B2:B4303,A14,'Diseases'!C2:C4303,B14,'Diseases'!D2:D4303,C14)} -> 12965 | E14: {=_xlfn.IFERROR(IF(INDEX('Diseases'!G2:G4303,MATCH(C14,'Diseases'!D2:D4303,0))="","",INDEX('Diseases'!G2:G4303,MATCH(C14,'Diseases'!D2:D4303,0))),"")} -> 14521657 | F14: {=_xlfn.IFERROR(IF(E14="","",D14/E14*100000),"")} -> 89.280445
A15: Injuries & External Causes | B15: March | C15: National Capital Region | D15: {=_xlfn.SUMIFS('Diseases'!F2:F4303,'Diseases'!B2:B4303,A15,'Diseases'!C2:C4303,B15,'Diseases'!D2:D4303,C15)} -> 11179 | E15: {=_xlfn.IFERROR(IF(INDEX('Diseases'!G2:G4303,MATCH(C15,'Diseases'!D2:D4303,0))="","",INDEX('Diseases'!G2:G4303,MATCH(C15,'Diseases'!D2:D4303,0))),"")} -> 14521657 | F15: {=_xlfn.IFERROR(IF(E15="","",D15/E15*100000),"")} -> 76.981573
A16: Digestive & Metabolic Disorders | B16: March | C16: National Capital Region | D16: {=_xlfn.SUMIFS('Diseases'!F2:F4303,'Diseases'!B2:B4303,A16,'Diseases'!C2:C4303,B16,'Diseases'!D2:D4303,C16)} -> 3722 | E16: {=_xlfn.IFERROR(IF(INDEX('Diseases'!G2:G4303,MATCH(C16,'Diseases'!D2:D4303,0))="","",INDEX('Diseases'!G2:G4303,MATCH(C16,'Diseases'!D2:D4303,0))),"")} -> 14521657 | F16: {=_xlfn.IFERROR(IF(E16="","",D16/E16*100000),"")} -> 25.630684
A17: Genitourinary & Reproductive Health | B17: March | C17: National Capital Region | D17: {=_xlfn.SUMIFS('Diseases'!F2:F4303,'Diseases'!B2:B4303,A17,'Diseases'!C2:C4303,B17,'Diseases'!D2:D4303,C17)} -> 1514 | E17: {=_xlfn.IFERROR(IF(INDEX('Diseases'!G2:G4303,MATCH(C17,'Diseases'!D2:D4303,0))="","",INDEX('Diseases'!G2:G4303,MATCH(C17,'Diseases'!D2:D4303,0))),"")} -> 14521657 | F17: {=_xlfn.IFERROR(IF(E17="","",D17/E17*100000),"")} -> 10.425807
A18: Symptoms & Other Findings | B18: March | C18: National Capital Region | D18: {=_xlfn.SUMIFS('Diseases'!F2:F4303,'Diseases'!B2:B4303,A18,'Diseases'!C2:C4303,B18,'Diseases'!D2:D4303,C18)} -> 1505 | E18: {=_xlfn.IFERROR(IF(INDEX('Diseases'!G2:G4303,MATCH(C18,'Diseases'!D2:D4303,0))="","",INDEX('Diseases'!G2:G4303,MATCH(C18,'Diseases'!D2:D4303,0))),"")} -> 14521657 | F18: {=_xlfn.IFERROR(IF(E18="","",D18/E18*100000),"")} -> 10.363831
A19: Respiratory Diseases | B19: April | C19: National Capital Region | D19: {=_xlfn.SUMIFS('Diseases'!F2:F4303,'Diseases'!B2:B4303,A19,'Diseases'!C2:C4303,B19,'Diseases'!D2:D4303,C19)} -> 300285 | E19: {=_xlfn.IFERROR(IF(INDEX('Diseases'!G2:G4303,MATCH(C19,'Diseases'!D2:D4303,0))="","",INDEX('Diseases'!G2:G4303,MATCH(C19,'Diseases'!D2:D4303,0))),"")} -> 14521657 | F19: {=_xlfn.IFERROR(IF(E19="","",D19/E19*100000),"")} -> 2067.8425
A20: Cardiovascular Diseases | B20: April | C20: National Capital Region | D20: {=_xlfn.SUMIFS('Diseases'!F2:F4303,'Diseases'!B2:B4303,A20,'Diseases'!C2:C4303,B20,'Diseases'!D2:D4303,C20)} -> 228345 | E20: {=_xlfn.IFERROR(IF(INDEX('Diseases'!G2:G4303,MATCH(C20,'Diseases'!D2:D4303,0))="","",INDEX('Diseases'!G2:G4303,MATCH(C20,'Diseases'!D2:D4303,0))),"")} -> 14521657 | F20: {=_xlfn.IFERROR(IF(E20="","",D20/E20*100000),"")} -> 1572.4445
A21: Injuries & External Causes | B21: April | C21: National Capital Region | D21: {=_xlfn.SUMIFS('Diseases'!F2:F4303,'Diseases'!B2:B4303,A21,'Diseases'!C2:C4303,B21,'Diseases'!D2:D4303,C21)} -> 152085 | E21: {=_xlfn.IFERROR(IF(INDEX('Diseases'!G2:G4303,MATCH(C21,'Diseases'!D2:D4303,0))="","",INDEX('Diseases'!G2:G4303,MATCH(C21,'Diseases'!D2:D4303,0))),"")} -> 14521657 | F21: {=_xlfn.IFERROR(IF(E21="","",D21/E21*100000),"")} -> 1047.2978
A22: Digestive & Metabolic Disorders | B22: April | C22: National Capital Region | D22: {=_xlfn.SUMIFS('Diseases'!F2:F4303,'Diseases'!B2:B4303,A22,'Diseases'!C2:C4303,B22,'Diseases'!D2:D4303,C22)} -> 85455 | E22: {=_xlfn.IFERROR(IF(INDEX('Diseases'!G2:G4303,MATCH(C22,'Diseases'!D2:D4303,0))="","",INDEX('Diseases'!G2:G4303,MATCH(C22,'Diseases'!D2:D4303,0))),"")} -> 14521657 | F22: {=_xlfn.IFERROR(IF(E22="","",D22/E22*100000),"")} -> 588.4659
A23: Skin & Soft Tissue Diseases | B23: April | C23: National Capital Region | D23: {=_xlfn.SUMIFS('Diseases'!F2:F4303,'Diseases'!B2:B4303,A23,'Diseases'!C2:C4303,B23,'Diseases'!D2:D4303,C23)} -> 20280 | E23: {=_xlfn.IFERROR(IF(INDEX('Diseases'!G2:G4303,MATCH(C23,'Diseases'!D2:D4303,0))="","",INDEX('Diseases'!G2:G4303,MATCH(C23,'Diseases'!D2:D4303,0))),"")} -> 14521657 | F23: {=_xlfn.IFERROR(IF(E23="","",D23/E23*100000),"")} -> 139.65348
A24: Respiratory Diseases | B24: May | C24: National Capital Region | D24: {=_xlfn.SUMIFS('Diseases'!F2:F4303,'Diseases'!B2:B4303,A24,'Diseases'!C2:C4303,B24,'Diseases'!D2:D4303,C24)} -> 19527 | E24: {=_xlfn.IFERROR(IF(INDEX('Diseases'!G2:G4303,MATCH(C24,'Diseases'!D2:D4303,0))="","",INDEX('Diseases'!G2:G4303,MATCH(C24,'Diseases'!D2:D4303,0))),"")} -> 14521657 | F24: {=_xlfn.IFERROR(IF(E24="","",D24/E24*100000),"")} -> 134.46813
A25: Cardiovascular Diseases | B25: May | C25: National Capital Region | D25: {=_xlfn.SUMIFS('Diseases'!F2:F4303,'Diseases'!B2:B4303,A25,'Diseases'!C2:C4303,B25,'Diseases'!D2:D4303,C25)} -> 17015 | E25: {=_xlfn.IFERROR(IF(INDEX('Diseases'!G2:G4303,MATCH(C25,'Diseases'!D2:D4303,0))="","",INDEX('Diseases'!G2:G4303,MATCH(C25,'Diseases'!D2:D4303,0))),"")} -> 14521657 | F25: {=_xlfn.IFERROR(IF(E25="","",D25/E25*100000),"")} -> 117.16982
A26: Digestive & Metabolic Disorders | B26: May | C26: National Capital Region | D26: {=_xlfn.SUMIFS('Diseases'!F2:F4303,'Diseases'!B2:B4303,A26,'Diseases'!C2:C4303,B26,'Diseases'!D2:D4303,C26)} -> 12754 | E26: {=_xlfn.IFERROR(IF(INDEX('Diseases'!G2:G4303,MATCH(C26,'Diseases'!D2:D4303,0))="","",INDEX('Diseases'!G2:G4303,MATCH(C26,'Diseases'!D2:D4303,0))),"")} -> 14521657 | F26: {=_xlfn.IFERROR(IF(E26="","",D26/E26*100000),"")} -> 87.827443
A27: Injuries & External Causes | B27: May | C27: National Capital Region | D27: {=_xlfn.SUMIFS('Diseases'!F2:F4303,'Diseases'!B2:B4303,A27,'Diseases'!C2:C4303,B27,'Diseases'!D2:D4303,C27)} -> 10609 | E27: {=_xlfn.IFERROR(IF(INDEX('Diseases'!G2:G4303,MATCH(C27,'Diseases'!D2:D4303,0))="","",INDEX('Diseases'!G2:G4303,MATCH(C27,'Diseases'!D2:D4303,0))),"")} -> 14521657 | F27: {=_xlfn.IFERROR(IF(E27="","",D27/E27*100000),"")} -> 73.056401
A28: Skin & Soft Tissue Diseases | B28: May | C28: National Capital Region | D28: {=_xlfn.SUMIFS('Diseases'!F2:F4303,'Diseases'!B2:B4303,A28,'Diseases'!C2:C4303,B28,'Diseases'!D2:D4303,C28)} -> 5788 | E28: {=_xlfn.IFERROR(IF(INDEX('Diseases'!G2:G4303,MATCH(C28,'Diseases'!D2:D4303,0))="","",INDEX('Diseases'!G2:G4303,MATCH(C28,'Diseases'!D2:D4303,0))),"")} -> 14521657 | F28: {=_xlfn.IFERROR(IF(E28="","",D28/E28*100000),"")} -> 39.85771
A29: Genitourinary & Reproductive Health | B29: May | C29: National Capital Region | D29: {=_xlfn.SUMIFS('Diseases'!F2:F4303,'Diseases'!B2:B4303,A29,'Diseases'!C2:C4303,B29,'Diseases'!D2:D4303,C29)} -> 3375 | E29: {=_xlfn.IFERROR(IF(INDEX('Diseases'!G2:G4303,MATCH(C29,'Diseases'!D2:D4303,0))="","",INDEX('Diseases'!G2:G4303,MATCH(C29,'Diseases'!D2:D4303,0))),"")} -> 14521657 | F29: {=_xlfn.IFERROR(IF(E29="","",D29/E29*100000),"")} -> 23.241149
A30: Cardiovascular Diseases | B30: June | C30: National Capital Region | D30: {=_xlfn.SUMIFS('Diseases'!F2:F4303,'Diseases'!B2:B4303,A30,'Diseases'!C2:C4303,B30,'Diseases'!D2:D4303,C30)} -> 27607 | E30: {=_xlfn.IFERROR(IF(INDEX('Diseases'!G2:G4303,MATCH(C30,'Diseases'!D2:D4303,0))="","",INDEX('Diseases'!G2:G4303,MATCH(C30,'Diseases'!D2:D4303,0))),"")} -> 14521657 | F30: {=_xlfn.IFERROR(IF(E30="","",D30/E30*100000),"")} -> 190.10916
A31: Respiratory Diseases | B31: June | C31: National Capital Region | D31: {=_xlfn.SUMIFS('Diseases'!F2:F4303,'Diseases'!B2:B4303,A31,'Diseases'!C2:C4303,B31,'Diseases'!D2:D4303,C31)} -> 23601 | E31: {=_xlfn.IFERROR(IF(INDEX('Diseases'!G2:G4303,MATCH(C31,'Diseases'!D2:D4303,0))="","",INDEX('Diseases'!G2:G4303,MATCH(C31,'Diseases'!D2:D4303,0))),"")} -> 14521657 | F31: {=_xlfn.IFERROR(IF(E31="","",D31/E31*100000),"")} -> 162.52278
A32: Injuries & External Causes | B32: June | C32: National Capital Region | D32: {=_xlfn.SUMIFS('Diseases'!F2:F4303,'Diseases'!B2:B4303,A32,'Diseases'!C2:C4303,B32,'Diseases'!D2:D4303,C32)} -> 23003 | E32: {=_xlfn.IFERROR(IF(INDEX('Diseases'!G2:G4303,MATCH(C32,'Diseases'!D2:D4303,0))="","",INDEX('Diseases'!G2:G4303,MATCH(C32,'Diseases'!D2:D4303,0))),"")} -> 14521657 | F32: {=_xlfn.IFERROR(IF(E32="","",D32/E32*100000),"")} -> 158.40479
A33: Digestive & Metabolic Disorders | B33: June | C33: National Capital Region | D33: {=_xlfn.SUMIFS('Diseases'!F2:F4303,'Diseases'!B2:B4303,A33,'Diseases'!C2:C4303,B33,'Diseases'!D2:D4303,C33)} -> 18497 | E33: {=_xlfn.IFERROR(IF(INDEX('Diseases'!G2:G4303,MATCH(C33,'Diseases'!D2:D4303,0))="","",INDEX('Diseases'!G2:G4303,MATCH(C33,'Diseases'!D2:D4303,0))),"")} -> 14521657 | F33: {=_xlfn.IFERROR(IF(E33="","",D33/E33*100000),"")} -> 127.37527
A34: Skin & Soft Tissue Diseases | B34: June | C34: National Capital Region | D34: {=_xlfn.SUMIFS('Diseases'!F2:F4303,'Diseases'!B2:B4303,A34,'Diseases'!C2:C4303,B34,'Diseases'!D2:D4303,C34)} -> 6214 | E34: {=_xlfn.IFERROR(IF(INDEX('Diseases'!G2:G4303,MATCH(C34,'Diseases'!D2:D4303,0))="","",INDEX('Diseases'!G2:G4303,MATCH(C34,'Diseases'!D2:D4303,0))),"")} -> 14521657 | F34: {=_xlfn.IFERROR(IF(E34="","",D34/E34*100000),"")} -> 42.79126
A35: Genitourinary & Reproductive Health | B35: June | C35: National Capital Region | D35: {=_xlfn.SUMIFS('Diseases'!F2:F4303,'Diseases'!B2:B4303,A35,'Diseases'!C2:C4303,B35,'Diseases'!D2:D4303,C35)} -> 4696 | E35: {=_xlfn.IFERROR(IF(INDEX('Diseases'!G2:G4303,MATCH(C35,'Diseases'!D2:D4303,0))="","",INDEX('Diseases'!G2:G4303,MATCH(C35,'Diseases'!D2:D4303,0))),"")} -> 14521657 | F35: {=_xlfn.IFERROR(IF(E35="","",D35/E35*100000),"")} -> 32.337907
A36: Respiratory Diseases | B36: July | C36: National Capital Region | D36: {=_xlfn.SUMIFS('Diseases'!F2:F4303,'Diseases'!B2:B4303,A36,'Diseases'!C2:C4303,B36,'Diseases'!D2:D4303,C36)} -> 33446 | E36: {=_xlfn.IFERROR(IF(INDEX('Diseases'!G2:G4303,MATCH(C36,'Diseases'!D2:D4303,0))="","",INDEX('Diseases'!G2:G4303,MATCH(C36,'Diseases'!D2:D4303,0))),"")} -> 14521657 | F36: {=_xlfn.IFERROR(IF(E36="","",D36/E36*100000),"")} -> 230.31807
A37: Cardiovascular Diseases | B37: July | C37: National Capital Region | D37: {=_xlfn.SUMIFS('Diseases'!F2:F4303,'Diseases'!B2:B4303,A37,'Diseases'!C2:C4303,B37,'Diseases'!D2:D4303,C37)} -> 26601 | E37: {=_xlfn.IFERROR(IF(INDEX('Diseases'!G2:G4303,MATCH(C37,'Diseases'!D2:D4303,0))="","",INDEX('Diseases'!G2:G4303,MATCH(C37,'Diseases'!D2:D4303,0))),"")} -> 14521657 | F37: {=_xlfn.IFERROR(IF(E37="","",D37/E37*100000),"")} -> 183.18157
A38: Injuries & External Causes | B38: July | C38: National Capital Region | D38: {=_xlfn.SUMIFS('Diseases'!F2:F4303,'Diseases'!B2:B4303,A38,'Diseases'!C2:C4303,B38,'Diseases'!D2:D4303,C38)} -> 19397 | E38: {=_xlfn.IFERROR(IF(INDEX('Diseases'!G2:G4303,MATCH(C38,'Diseases'!D2:D4303,0))="","",INDEX('Diseases'!G2:G4303,MATCH(C38,'Diseases'!D2:D4303,0))),"")} -> 14521657 | F38: {=_xlfn.IFERROR(IF(E38="","",D38/E38*100000),"")} -> 133.57291
A39: Digestive & Metabolic Disorders | B39: July | C39: National Capital Region | D39: {=_xlfn.SUMIFS('Diseases'!F2:F4303,'Diseases'!B2:B4303,A39,'Diseases'!C2:C4303,B39,'Diseases'!D2:D4303,C39)} -> 14499 | E39: {=_xlfn.IFERROR(IF(INDEX('Diseases'!G2:G4303,MATCH(C39,'Diseases'!D2:D4303,0))="","",INDEX('Diseases'!G2:G4303,MATCH(C39,'Diseases'!D2:D4303,0))),"")} -> 14521657 | F39: {=_xlfn.IFERROR(IF(E39="","",D39/E39*100000),"")} -> 99.843978
A40: Genitourinary & Reproductive Health | B40: July | C40: National Capital Region | D40: {=_xlfn.SUMIFS('Diseases'!F2:F4303,'Diseases'!B2:B4303,A40,'Diseases'!C2:C4303,B40,'Diseases'!D2:D4303,C40)} -> 5711 | E40: {=_xlfn.IFERROR(IF(INDEX('Diseases'!G2:G4303,MATCH(C40,'Diseases'!D2:D4303,0))="","",INDEX('Diseases'!G2:G4303,MATCH(C40,'Diseases'!D2:D4303,0))),"")} -> 14521657 | F40: {=_xlfn.IFERROR(IF(E40="","",D40/E40*100000),"")} -> 39.327468
...

Sheet Chart - National Capital Region
A1: Monthly Incidence Rate (per 100k) by Disease — National Capital Region
A3: Month | B3: Cardiovascular Diseases | C3: Digestive & Metabolic Disorders | D3: Genitourinary & Reproductive Health | E3: Injuries & External Causes | F3: Respiratory Diseases | G3: Skin & Soft Tissue Diseases | H3: Symptoms & Other Findings
A4: January | B4: {=_xlfn.IFERROR(_xlfn.SUMIFS('Total Cases'!F2:F1312,'Total Cases'!A2:A1312,B$3,'Total Cases'!B2:B1312,$A4,'Total Cases'!C2:C1312,"National Capital Region"),0)} -> 67.616251 | C4: {=_xlfn.IFERROR(_xlfn.SUMIFS('Total Cases'!F2:F1312,'Total Cases'!A2:A1312,C$3,'Total Cases'!B2:B1312,$A4,'Total Cases'!C2:C1312,"National Capital Region"),0)} -> 9.792271 | D4: {=_xlfn.IFERROR(_xlfn.SUMIFS('Total Cases'!F2:F1312,'Total Cases'!A2:A1312,D$3,'Total Cases'!B2:B1312,$A4,'Total Cases'!C2:C1312,"National Capital Region"),0)} -> 0 | E4: {=_xlfn.IFERROR(_xlfn.SUMIFS('Total Cases'!F2:F1312,'Total Cases'!A2:A1312,E$3,'Total Cases'!B2:B1312,$A4,'Total Cases'!C2:C1312,"National Capital Region"),0)} -> 44.740073 | F4: {=_xlfn.IFERROR(_xlfn.SUMIFS('Total Cases'!F2:F1312,'Total Cases'!A2:A1312,F$3,'Total Cases'!B2:B1312,$A4,'Total Cases'!C2:C1312,"National Capital Region"),0)} -> 157.03442 | G4: {=_xlfn.IFERROR(_xlfn.SUMIFS('Total Cases'!F2:F1312,'Total Cases'!A2:A1312,G$3,'Total Cases'!B2:B1312,$A4,'Total Cases'!C2:C1312,"National Capital Region"),0)} -> 10.563533 | H4: {=_xlfn.IFERROR(_xlfn.SUMIFS('Total Cases'!F2:F1312,'Total Cases'!A2:A1312,H$3,'Total Cases'!B2:B1312,$A4,'Total Cases'!C2:C1312,"National Capital Region"),0)} -> 0
A5: February | B5: {=_xlfn.IFERROR(_xlfn.SUMIFS('Total Cases'!F2:F1312,'Total Cases'!A2:A1312,B$3,'Total Cases'!B2:B1312,$A5,'Total Cases'!C2:C1312,"National Capital Region"),0)} -> 51.832928 | C5: {=_xlfn.IFERROR(_xlfn.SUMIFS('Total Cases'!F2:F1312,'Total Cases'!A2:A1312,C$3,'Total Cases'!B2:B1312,$A5,'Total Cases'!C2:C1312,"National Capital Region"),0)} -> 28.653755 | D5: {=_xlfn.IFERROR(_xlfn.SUMIFS('Total Cases'!F2:F1312,'Total Cases'!A2:A1312,D$3,'Total Cases'!B2:B1312,$A5,'Total Cases'!C2:C1312,"National Capital Region"),0)} -> 13.049475 | E5: {=_xlfn.IFERROR(_xlfn.SUMIFS('Total Cases'!F2:F1312,'Total Cases'!A2:A1312,E$3,'Total Cases'!B2:B1312,$A5,'Total Cases'!C2:C1312,"National Capital Region"),0)} -> 70.081534 | F5: {=_xlfn.IFERROR(_xlfn.SUMIFS('Total Cases'!F2:F1312,'Total Cases'!A2:A1312,F$3,'Total Cases'!B2:B1312,$A5,'Total Cases'!C2:C1312,"National Capital Region"),0)} -> 157.17215 | G5: {=_xlfn.IFERROR(_xlfn.SUMIFS('Total Cases'!F2:F1312,'Total Cases'!A2:A1312,G$3,'Total Cases'!B2:B1312,$A5,'Total Cases'!C2:C1312,"National Capital Region"),0)} -> 0 | H5: {=_xlfn.IFERROR(_xlfn.SUMIFS('Total Cases'!F2:F1312,'Total Cases'!A2:A1312,H$3,'Total Cases'!B2:B1312,$A5,'Total Cases'!C2:C1312,"National Capital Region"),0)} -> 38.852316
A6: March | B6: {=_xlfn.IFERROR(_xlfn.SUMIFS('Total Cases'!F2:F1312,'Total Cases'!A2:A1312,B$3,'Total Cases'!B2:B1312,$A6,'Total Cases'!C2:C1312,"National Capital Region"),0)} -> 89.280445 | C6: {=_xlfn.IFERROR(_xlfn.SUMIFS('Total Cases'!F2:F1312,'Total Cases'!A2:A1312,C$3,'Total Cases'!B2:B1312,$A6,'Total Cases'!C2:C1312,"National Capital Region"),0)} -> 25.630684 | D6: {=_xlfn.IFERROR(_xlfn.SUMIFS('Total Cases'!F2:F1312,'Total Cases'!A2:A1312,D$3,'Total Cases'!B2:B1312,$A6,'Total Cases'!C2:C1312,"National Capital Region"),0)} -> 10.425807 | E6: {=_xlfn.IFERROR(_xlfn.SUMIFS('Total Cases'!F2:F1312,'Total Cases'!A2:A1312,E$3,'Total Cases'!B2:B1312,$A6,'Total Cases'!C2:C1312,"National Capital Region"),0)} -> 76.981573 | F6: {=_xlfn.IFERROR(_xlfn.SUMIFS('Total Cases'!F2:F1312,'Total Cases'!A2:A1312,F$3,'Total Cases'!B2:B1312,$A6,'Total Cases'!C2:C1312,"National Capital Region"),0)} -> 155.32663 | G6: {=_xlfn.IFERROR(_xlfn.SUMIFS('Total Cases'!F2:F1312,'Total Cases'!A2:A1312,G$3,'Total Cases'!B2:B1312,$A6,'Total Cases'!C2:C1312,"National Capital Region"),0)} -> 0 | H6: {=_xlfn.IFERROR(_xlfn.SUMIFS('Total Cases'!F2:F1312,'Total Cases'!A2:A1312,H$3,'Total Cases'!B2:B1312,$A6,'Total Cases'!C2:C1312,"National Capital Region"),0)} -> 10.363831
A7: April | B7: {=_xlfn.IFERROR(_xlfn.SUMIFS('Total Cases'!F2:F1312,'Total Cases'!A2:A1312,B$3,'Total Cases'!B2:B1312,$A7,'Total Cases'!C2:C1312,"National Capital Region"),0)} -> 1572.4445 | C7: {=_xlfn.IFERROR(_xlfn.SUMIFS('Total Cases'!F2:F1312,'Total Cases'!A2:A1312,C$3,'Total Cases'!B2:B1312,$A7,'Total Cases'!C2:C1312,"National Capital Region"),0)} -> 588.4659 | D7: {=_xlfn.IFERROR(_xlfn.SUMIFS('Total Cases'!F2:F1312,'Total Cases'!A2:A1312,D$3,'Total Cases'!B2:B1312,$A7,'Total Cases'!C2:C1312,"National Capital Region"),0)} -> 0 | E7: {=_xlfn.IFERROR(_xlfn.SUMIFS('Total Cases'!F2:F1312,'Total Cases'!A2:A1312,E$3,'Total Cases'!B2:B1312,$A7,'Total Cases'!C2:C1312,"National Capital Region"),0)} -> 1047.2978 | F7: {=_xlfn.IFERROR(_xlfn.SUMIFS('Total Cases'!F2:F1312,'Total Cases'!A2:A1312,F$3,'Total Cases'!B2:B1312,$A7,'Total Cases'!C2:C1312,"National Capital Region"),0)} -> 2067.8425 | G7: {=_xlfn.IFERROR(_xlfn.SUMIFS('Total Cases'!F2:F1312,'Total Cases'!A2:A1312,G$3,'Total Cases'!B2:B1312,$A7,'Total Cases'!C2:C1312,"National Capital Region"),0)} -> 139.65348 | H7: {=_xlfn.IFERROR(_xlfn.SUMIFS('Total Cases'!F2:F1312,'Total Cases'!A2:A1312,H$3,'Total Cases'!B2:B1312,$A7,'Total Cases'!C2:C1312,"National Capital Region"),0)} -> 0
A8: May | B8: {=_xlfn.IFERROR(_xlfn.SUMIFS('Total Cases'!F2:F1312,'Total Cases'!A2:A1312,B$3,'Total Cases'!B2:B1312,$A8,'Total Cases'!C2:C1312,"National Capital Region"),0)} -> 117.16982 | C8: {=_xlfn.IFERROR(_xlfn.SUMIFS('Total Cases'!F2:F1312,'Total Cases'!A2:A1312,C$3,'Total Cases'!B2:B1312,$A8,'Total Cases'!C2:C1312,"National Capital Region"),0)} -> 87.827443 | D8: {=_xlfn.IFERROR(_xlfn.SUMIFS('Total Cases'!F2:F1312,'Total Cases'!A2:A1312,D$3,'Total Cases'!B2:B1312,$A8,'Total Cases'!C2:C1312,"National Capital Region"),0)} -> 23.241149 | E8: {=_xlfn.IFERROR(_xlfn.SUMIFS('Total Cases'!F2:F1312,'Total Cases'!A2:A1312,E$3,'Total Cases'!B2:B1312,$A8,'Total Cases'!C2:C1312,"National Capital Region"),0)} -> 73.056401 | F8: {=_xlfn.IFERROR(_xlfn.SUMIFS('Total Cases'!F2:F1312,'Total Cases'!A2:A1312,F$3,'Total Cases'!B2:B1312,$A8,'Total Cases'!C2:C1312,"National Capital Region"),0)} -> 134.46813 | G8: {=_xlfn.IFERROR(_xlfn.SUMIFS('Total Cases'!F2:F1312,'Total Cases'!A2:A1312,G$3,'Total Cases'!B2:B1312,$A8,'Total Cases'!C2:C1312,"National Capital Region"),0)} -> 39.85771 | H8: {=_xlfn.IFERROR(_xlfn.SUMIFS('Total Cases'!F2:F1312,'Total Cases'!A2:A1312,H$3,'Total Cases'!B2:B1312,$A8,'Total Cases'!C2:C1312,"National Capital Region"),0)} -> 0
A9: June | B9: {=_xlfn.IFERROR(_xlfn.SUMIFS('Total Cases'!F2:F1312,'Total Cases'!A2:A1312,B$3,'Total Cases'!B2:B1312,$A9,'Total Cases'!C2:C1312,"National Capital Region"),0)} -> 190.10916 | C9: {=_xlfn.IFERROR(_xlfn.SUMIFS('Total Cases'!F2:F1312,'Total Cases'!A2:A1312,C$3,'Total Cases'!B2:B1312,$A9,'Total Cases'!C2:C1312,"National Capital Region"),0)} -> 127.37527 | D9: {=_xlfn.IFERROR(_xlfn.SUMIFS('Total Cases'!F2:F1312,'Total Cases'!A2:A1312,D$3,'Total Cases'!B2:B1312,$A9,'Total Cases'!C2:C1312,"National Capital Region"),0)} -> 32.337907 | E9: {=_xlfn.IFERROR(_xlfn.SUMIFS('Total Cases'!F2:F1312,'Total Cases'!A2:A1312,E$3,'Total Cases'!B2:B1312,$A9,'Total Cases'!C2:C1312,"National Capital Region"),0)} -> 158.40479 | F9: {=_xlfn.IFERROR(_xlfn.SUMIFS('Total Cases'!F2:F1312,'Total Cases'!A2:A1312,F$3,'Total Cases'!B2:B1312,$A9,'Total Cases'!C2:C1312,"National Capital Region"),0)} -> 162.52278 | G9: {=_xlfn.IFERROR(_xlfn.SUMIFS('Total Cases'!F2:F1312,'Total Cases'!A2:A1312,G$3,'Total Cases'!B2:B1312,$A9,'Total Cases'!C2:C1312,"National Capital Region"),0)} -> 42.79126 | H9: {=_xlfn.IFERROR(_xlfn.SUMIFS('Total Cases'!F2:F1312,'Total Cases'!A2:A1312,H$3,'Total Cases'!B2:B1312,$A9,'Total Cases'!C2:C1312,"National Capital Region"),0)} -> 0
A10: July | B10: {=_xlfn.IFERROR(_xlfn.SUMIFS('Total Cases'!F2:F1312,'Total Cases'!A2:A1312,B$3,'Total Cases'!B2:B1312,$A10,'Total Cases'!C2:C1312,"National Capital Region"),0)} -> 183.18157 | C10: {=_xlfn.IFERROR(_xlfn.SUMIFS('Total Cases'!F2:F1312,'Total Cases'!A2:A1312,C$3,'Total Cases'!B2:B1312,$A10,'Total Cases'!C2:C1312,"National Capital Region"),0)} -> 99.843978 | D10: {=_xlfn.IFERROR(_xlfn.SUMIFS('Total Cases'!F2:F1312,'Total Cases'!A2:A1312,D$3,'Total Cases'!B2:B1312,$A10,'Total Cases'!C2:C1312,"National Capital Region"),0)} -> 39.327468 | E10: {=_xlfn.IFERROR(_xlfn.SUMIFS('Total Cases'!F2:F1312,'Total Cases'!A2:A1312,E$3,'Total Cases'!B2:B1312,$A10,'Total Cases'!C2:C1312,"National Capital Region"),0)} -> 133.57291 | F10: {=_xlfn.IFERROR(_xlfn.SUMIFS('Total Cases'!F2:F1312,'Total Cases'!A2:A1312,F$3,'Total Cases'!B2:B1312,$A10,'Total Cases'!C2:C1312,"National Capital Region"),0)} -> 230.31807 | G10: {=_xlfn.IFERROR(_xlfn.SUMIFS('Total Cases'!F2:F1312,'Total Cases'!A2:A1312,G$3,'Total Cases'!B2:B1312,$A10,'Total Cases'!C2:C1312,"National Capital Region"),0)} -> 29.376813 | H10: {=_xlfn.IFERROR(_xlfn.SUMIFS('Total Cases'!F2:F1312,'Total Cases'!A2:A1312,H$3,'Total Cases'!B2:B1312,$A10,'Total Cases'!C2:C1312,"National Capital Region"),0)} -> 0
A11: August | B11: {=_xlfn.IFERROR(_xlfn.SUMIFS('Total Cases'!F2:F1312,'Total Cases'!A2:A1312,B$3,'Total Cases'!B2:B1312,$A11,'Total Cases'!C2:C1312,"National Capital Region"),0)} -> 129.93696 | C11: {=_xlfn.IFERROR(_xlfn.SUMIFS('Total Cases'!F2:F1312,'Total Cases'!A2:A1312,C$3,'Total Cases'!B2:B1312,$A11,'Total Cases'!C2:C1312,"National Capital Region"),0)} -> 69.310272 | D11: {=_xlfn.IFERROR(_xlfn.SUMIFS('Total Cases'!F2:F1312,'Total Cases'!A2:A1312,D$3,'Total Cases'!B2:B1312,$A11,'Total Cases'!C2:C1312,"National Capital Region"),0)} -> 34.162768 | E11: {=_xlfn.IFERROR(_xlfn.SUMIFS('Total Cases'!F2:F1312,'Total Cases'!A2:A1312,E$3,'Total Cases'!B2:B1312,$A11,'Total Cases'!C2:C1312,"National Capital Region"),0)} -> 93.315797 | F11: {=_xlfn.IFERROR(_xlfn.SUMIFS('Total Cases'!F2:F1312,'Total Cases'!A2:A1312,F$3,'Total Cases'!B2:B1312,$A11,'Total Cases'!C2:C1312,"National Capital Region"),0)} -> 223.31474 | G11: {=_xlfn.IFERROR(_xlfn.SUMIFS('Total Cases'!F2:F1312,'Total Cases'!A2:A1312,G$3,'Total Cases'!B2:B1312,$A11,'Total Cases'!C2:C1312,"National Capital Region"),0)} -> 17.091713 | H11: {=_xlfn.IFERROR(_xlfn.SUMIFS('Total Cases'!F2:F1312,'Total Cases'!A2:A1312,H$3,'Total Cases'!B2:B1312,$A11,'Total Cases'!C2:C1312,"National Capital Region"),0)} -> 0
A12: September | B12: {=_xlfn.IFERROR(_xlfn.SUMIFS('Total Cases'!F2:F1312,'Total Cases'!A2:A1312,B$3,'Total Cases'!B2:B1312,$A12,'Total Cases'!C2:C1312,"National Capital Region"),0)} -> 185.33698 | C12: {=_xlfn.IFERROR(_xlfn.SUMIFS('Total Cases'!F2:F1312,'Total Cases'!A2:A1312,C$3,'Total Cases'!B2:B1312,$A12,'Total Cases'!C2:C1312,"National Capital Region"),0)} -> 126.97587 | D12: {=_xlfn.IFERROR(_xlfn.SUMIFS('Total Cases'!F2:F1312,'Total Cases'!A2:A1312,D$3,'Total Cases'!B2:B1312,$A12,'Total Cases'!C2:C1312,"National Capital Region"),0)} -> 41.104125 | E12: {=_xlfn.IFERROR(_xlfn.SUMIFS('Total Cases'!F2:F1312,'Total Cases'!A2:A1312,E$3,'Total Cases'!B2:B1312,$A12,'Total Cases'!C2:C1312,"National Capital Region"),0)} -> 66.266542 | F12: {=_xlfn.IFERROR(_xlfn.SUMIFS('Total Cases'!F2:F1312,'Total Cases'!A2:A1312,F$3,'Total Cases'!B2:B1312,$A12,'Total Cases'!C2:C1312,"National Capital Region"),0)} -> 400.49837 | G12: {=_xlfn.IFERROR(_xlfn.SUMIFS('Total Cases'!F2:F1312,'Total Cases'!A2:A1312,G$3,'Total Cases'!B2:B1312,$A12,'Total Cases'!C2:C1312,"National Capital Region"),0)} -> 0 | H12: {=_xlfn.IFERROR(_xlfn.SUMIFS('Total Cases'!F2:F1312,'Total Cases'!A2:A1312,H$3,'Total Cases'!B2:B1312,$A12,'Total Cases'!C2:C1312,"National Capital Region"),0)} -> 0
A13: October | B13: {=_xlfn.IFERROR(_xlfn.SUMIFS('Total Cases'!F2:F1312,'Total Cases'!A2:A1312,B$3,'Total Cases'!B2:B1312,$A13,'Total Cases'!C2:C1312,"National Capital Region"),0)} -> 247.24451 | C13: {=_xlfn.IFERROR(_xlfn.SUMIFS('Total Cases'!F2:F1312,'Total Cases'!A2:A1312,C$3,'Total Cases'!B2:B1312,$A13,'Total Cases'!C2:C1312,"National Capital Region"),0)} -> 143.35141 | D13: {=_xlfn.IFERROR(_xlfn.SUMIFS('Total Cases'!F2:F1312,'Total Cases'!A2:A1312,D$3,'Total Cases'!B2:B1312,$A13,'Total Cases'!C2:C1312,"National Capital Region"),0)} -> 47.976619 | E13: {=_xlfn.IFERROR(_xlfn.SUMIFS('Total Cases'!F2:F1312,'Total Cases'!A2:A1312,E$3,'Total Cases'!B2:B1312,$A13,'Total Cases'!C2:C1312,"National Capital Region"),0)} -> 83.46155 | F13: {=_xlfn.IFERROR(_xlfn.SUMIFS('Total Cases'!F2:F1312,'Total Cases'!A2:A1312,F$3,'Total Cases'!B2:B1312,$A13,'Total Cases'!C2:C1312,"National Capital Region"),0)} -> 493.16686 | G13: {=_xlfn.IFERROR(_xlfn.SUMIFS('Total Cases'!F2:F1312,'Total Cases'!A2:A1312,G$3,'Total Cases'!B2:B1312,$A13,'Total Cases'!C2:C1312,"National Capital Region"),0)} -> 0 | H13: {=_xlfn.IFERROR(_xlfn.SUMIFS('Total Cases'!F2:F1312,'Total Cases'!A2:A1312,H$3,'Total Cases'!B2:B1312,$A13,'Total Cases'!C2:C1312,"National Capital Region"),0)} -> 0
A14: November | B14: {=_xlfn.IFERROR(_xlfn.SUMIFS('Total Cases'!F2:F1312,'Total Cases'!A2:A1312,B$3,'Total Cases'!B2:B1312,$A14,'Total Cases'!C2:C1312,"National Capital Region"),0)} -> 218.29465 | C14: {=_xlfn.IFERROR(_xlfn.SUMIFS('Total Cases'!F2:F1312,'Total Cases'!A2:A1312,C$3,'Total Cases'!B2:B1312,$A14,'Total Cases'!C2:C1312,"National Capital Region"),0)} -> 147.86191 | D14: {=_xlfn.IFERROR(_xlfn.SUMIFS('Total Cases'!F2:F1312,'Total Cases'!A2:A1312,D$3,'Total Cases'!B2:B1312,$A14,'Total Cases'!C2:C1312,"National Capital Region"),0)} -> 40.078071 | E14: {=_xlfn.IFERROR(_xlfn.SUMIFS('Total Cases'!F2:F1312,'Total Cases'!A2:A1312,E$3,'Total Cases'!B2:B1312,$A14,'Total Cases'!C2:C1312,"National Capital Region"),0)} -> 66.734809 | F14: {=_xlfn.IFERROR(_xlfn.SUMIFS('Total Cases'!F2:F1312,'Total Cases'!A2:A1312,F$3,'Total Cases'!B2:B1312,$A14,'Total Cases'!C2:C1312,"National Capital Region"),0)} -> 262.31166 | G14: {=_xlfn.IFERROR(_xlfn.SUMIFS('Total Cases'!F2:F1312,'Total Cases'!A2:A1312,G$3,'Total Cases'!B2:B1312,$A14,'Total Cases'!C2:C1312,"National Capital Region"),0)} -> 20.755207 | H14: {=_xlfn.IFERROR(_xlfn.SUMIFS('Total Cases'!F2:F1312,'Total Cases'!A2:A1312,H$3,'Total Cases'!B2:B1312,$A14,'Total Cases'!C2:C1312,"National Capital Region"),0)} -> 0
A15: December | B15: {=_xlfn.IFERROR(_xlfn.SUMIFS('Total Cases'!F2:F1312,'Total Cases'!A2:A1312,B$3,'Total Cases'!B2:B1312,$A15,'Total Cases'!C2:C1312,"National Capital Region"),0)} -> 193.66247 | C15: {=_xlfn.IFERROR(_xlfn.SUMIFS('Total Cases'!F2:F1312,'Total Cases'!A2:A1312,C$3,'Total Cases'!B2:B1312,$A15,'Total Cases'!C2:C1312,"National Capital Region"),0)} -> 125.83963 | D15: {=_xlfn.IFERROR(_xlfn.SUMIFS('Total Cases'!F2:F1312,'Total Cases'!A2:A1312,D$3,'Total Cases'!B2:B1312,$A15,'Total Cases'!C2:C1312,"National Capital Region"),0)} -> 32.730425 | E15: {=_xlfn.IFERROR(_xlfn.SUMIFS('Total Cases'!F2:F1312,'Total Cases'!A2:A1312,E$3,'Total Cases'!B2:B1312,$A15,'Total Cases'!C2:C1312,"National Capital Region"),0)} -> 55.475763 | F15: {=_xlfn.IFERROR(_xlfn.SUMIFS('Total Cases'!F2:F1312,'Total Cases'!A2:A1312,F$3,'Total Cases'!B2:B1312,$A15,'Total Cases'!C2:C1312,"National Capital Region"),0)} -> 305.23376 | G15: {=_xlfn.IFERROR(_xlfn.SUMIFS('Total Cases'!F2:F1312,'Total Cases'!A2:A1312,G$3,'Total Cases'!B2:B1312,$A15,'Total Cases'!C2:C1312,"National Capital Region"),0)} -> 0 | H15: {=_xlfn.IFERROR(_xlfn.SUMIFS('Total Cases'!F2:F1312,'Total Cases'!A2:A1312,H$3,'Total Cases'!B2:B1312,$A15,'Total Cases'!C2:C1312,"National Capital Region"),0)} -> 0

Sheet Chart - Cordillera Administrati
A1: Monthly Incidence Rate (per 100k) by Disease — Cordillera Administrative Region
A3: Month | B3: Cardiovascular Diseases | C3: Digestive & Metabolic Disorders | D3: Genitourinary & Reproductive Health | E3: Health Services & Screening | F3: Infectious & Parasitic Diseases | G3: Injuries & External Causes | H3: Respiratory Diseases | I3: Symptoms & Other Findings
A4: January | B4: {=_xlfn.IFERROR(_xlfn.SUMIFS('Total Cases'!F2:F1312,'Total Cases'!A2:A1312,B$3,'Total Cases'!B2:B1312,$A4,'Total Cases'!C2:C1312,"Cordillera Administrative Region"),0)} -> 430.83188 | C4: {=_xlfn.IFERROR(_xlfn.SUMIFS('Total Cases'!F2:F1312,'Total Cases'!A2:A1312,C$3,'Total Cases'!B2:B1312,$A4,'Total Cases'!C2:C1312,"Cordillera Administrative Region"),0)} -> 81.204473 | D4: {=_xlfn.IFERROR(_xlfn.SUMIFS('Total Cases'!F2:F1312,'Total Cases'!A2:A1312,D$3,'Total Cases'!B2:B1312,$A4,'Total Cases'!C2:C1312,"Cordillera Administrative Region"),0)} -> 199.063 | E4: {=_xlfn.IFERROR(_xlfn.SUMIFS('Total Cases'!F2:F1312,'Total Cases'!A2:A1312,E$3,'Total Cases'!B2:B1312,$A4,'Total Cases'!C2:C1312,"Cordillera Administrative Region"),0)} -> 99.504823 | F4: {=_xlfn.IFERROR(_xlfn.SUMIFS('Total Cases'!F2:F1312,'Total Cases'!A2:A1312,F$3,'Total Cases'!B2:B1312,$A4,'Total Cases'!C2:C1312,"Cordillera Administrative Region"),0)} -> 0 | G4: {=_xlfn.IFERROR(_xlfn.SUMIFS('Total Cases'!F2:F1312,'Total Cases'!A2:A1312,G$3,'Total Cases'!B2:B1312,$A4,'Total Cases'!C2:C1312,"Cordillera Administrative Region"),0)} -> 101.15879 | H4: {=_xlfn.IFERROR(_xlfn.SUMIFS('Total Cases'!F2:F1312,'Total Cases'!A2:A1312,H$3,'Total Cases'!B2:B1312,$A4,'Total Cases'!C2:C1312,"Cordillera Administrative Region"),0)} -> 1152.9755 | I4: {=_xlfn.IFERROR(_xlfn.SUMIFS('Total Cases'!F2:F1312,'Total Cases'!A2:A1312,I$3,'Total Cases'!B2:B1312,$A4,'Total Cases'!C2:C1312,"Cordillera Administrative Region"),0)} -> 98.170979
A5: February | B5: {=_xlfn.IFERROR(_xlfn.SUMIFS('Total Cases'!F2:F1312,'Total Cases'!A2:A1312,B$3,'Total Cases'!B2:B1312,$A5,'Total Cases'!C2:C1312,"Cordillera Administrative Region"),0)} -> 389.74946 | C5: {=_xlfn.IFERROR(_xlfn.SUMIFS('Total Cases'!F2:F1312,'Total Cases'!A2:A1312,C$3,'Total Cases'!B2:B1312,$A5,'Total Cases'!C2:C1312,"Cordillera Administrative Region"),0)} -> 241.53262 | D5: {=_xlfn.IFERROR(_xlfn.SUMIFS('Total Cases'!F2:F1312,'Total Cases'!A2:A1312,D$3,'Total Cases'!B2:B1312,$A5,'Total Cases'!C2:C1312,"Cordillera Administrative Region"),0)} -> 197.56909 | E5: {=_xlfn.IFERROR(_xlfn.SUMIFS('Total Cases'!F2:F1312,'Total Cases'!A2:A1312,E$3,'Total Cases'!B2:B1312,$A5,'Total Cases'!C2:C1312,"Cordillera Administrative Region"),0)} -> 88.300527 | F5: {=_xlfn.IFERROR(_xlfn.SUMIFS('Total Cases'!F2:F1312,'Total Cases'!A2:A1312,F$3,'Total Cases'!B2:B1312,$A5,'Total Cases'!C2:C1312,"Cordillera Administrative Region"),0)} -> 55.327883 | G5: {=_xlfn.IFERROR(_xlfn.SUMIFS('Total Cases'!F2:F1312,'Total Cases'!A2:A1312,G$3,'Total Cases'!B2:B1312,$A5,'Total Cases'!C2:C1312,"Cordillera Administrative Region"),0)} -> 103.98654 | H5: {=_xlfn.IFERROR(_xlfn.SUMIFS('Total Cases'!F2:F1312,'Total Cases'!A2:A1312,H$3,'Total Cases'!B2:B1312,$A5,'Total Cases'!C2:C1312,"Cordillera Administrative Region"),0)} -> 1044.774 | I5: {=_xlfn.IFERROR(_xlfn.SUMIFS('Total Cases'!F2:F1312,'Total Cases'!A2:A1312,I$3,'Total Cases'!B2:B1312,$A5,'Total Cases'!C2:C1312,"Cordillera Administrative Region"),0)} -> 0
A6: March | B6: {=_xlfn.IFERROR(_xlfn.SUMIFS('Total Cases'!F2:F1312,'Total Cases'!A2:A1312,B$3,'Total Cases'!B2:B1312,$A6,'Total Cases'!C2:C1312,"Cordillera Administrative Region"),0)} -> 316.76147 | C6: {=_xlfn.IFERROR(_xlfn.SUMIFS('Total Cases'!F2:F1312,'Total Cases'!A2:A1312,C$3,'Total Cases'!B2:B1312,$A6,'Total Cases'!C2:C1312,"Cordillera Administrative Region"),0)} -> 200.66361 | D6: {=_xlfn.IFERROR(_xlfn.SUMIFS('Total Cases'!F2:F1312,'Total Cases'!A2:A1312,D$3,'Total Cases'!B2:B1312,$A6,'Total Cases'!C2:C1312,"Cordillera Administrative Region"),0)} -> 165.07663 | E6: {=_xlfn.IFERROR(_xlfn.SUMIFS('Total Cases'!F2:F1312,'Total Cases'!A2:A1312,E$3,'Total Cases'!B2:B1312,$A6,'Total Cases'!C2:C1312,"Cordillera Administrative Region"),0)} -> 0 | F6: {=_xlfn.IFERROR(_xlfn.SUMIFS('Total Cases'!F2:F1312,'Total Cases'!A2:A1312,F$3,'Total Cases'!B2:B1312,$A6,'Total Cases'!C2:C1312,"Cordillera Administrative Region"),0)} -> 0 | G6: {=_xlfn.IFERROR(_xlfn.SUMIFS('Total Cases'!F2:F1312,'Total Cases'!A2:A1312,G$3,'Total Cases'!B2:B1312,$A6,'Total Cases'!C2:C1312,"Cordillera Administrative Region"),0)} -> 78.750198 | H6: {=_xlfn.IFERROR(_xlfn.SUMIFS('Total Cases'!F2:F1312,'Total Cases'!A2:A1312,H$3,'Total Cases'!B2:B1312,$A6,'Total Cases'!C2:C1312,"Cordillera Administrative Region"),0)} -> 910.42912 | I6: {=_xlfn.IFERROR(_xlfn.SUMIFS('Total Cases'!F2:F1312,'Total Cases'!A2:A1312,I$3,'Total Cases'!B2:B1312,$A6,'Total Cases'!C2:C1312,"Cordillera Administrative Region"),0)} -> 0
A7: April | B7: {=_xlfn.IFERROR(_xlfn.SUMIFS('Total Cases'!F2:F1312,'Total Cases'!A2:A1312,B$3,'Total Cases'!B2:B1312,$A7,'Total Cases'!C2:C1312,"Cordillera Administrative Region"),0)} -> 5465.2958 | C7: {=_xlfn.IFERROR(_xlfn.SUMIFS('Total Cases'!F2:F1312,'Total Cases'!A2:A1312,C$3,'Total Cases'!B2:B1312,$A7,'Total Cases'!C2:C1312,"Cordillera Administrative Region"),0)} -> 2266.4691 | D7: {=_xlfn.IFERROR(_xlfn.SUMIFS('Total Cases'!F2:F1312,'Total Cases'!A2:A1312,D$3,'Total Cases'!B2:B1312,$A7,'Total Cases'!C2:C1312,"Cordillera Administrative Region"),0)} -> 1130.8336 | E7: {=_xlfn.IFERROR(_xlfn.SUMIFS('Total Cases'!F2:F1312,'Total Cases'!A2:A1312,E$3,'Total Cases'!B2:B1312,$A7,'Total Cases'!C2:C1312,"Cordillera Administrative Region"),0)} -> 0 | F7: {=_xlfn.IFERROR(_xlfn.SUMIFS('Total Cases'!F2:F1312,'Total Cases'!A2:A1312,F$3,'Total Cases'!B2:B1312,$A7,'Total Cases'!C2:C1312,"Cordillera Administrative Region"),0)} -> 0 | G7: {=_xlfn.IFERROR(_xlfn.SUMIFS('Total Cases'!F2:F1312,'Total Cases'!A2:A1312,G$3,'Total Cases'!B2:B1312,$A7,'Total Cases'!C2:C1312,"Cordillera Administrative Region"),0)} -> 2692.2324 | H7: {=_xlfn.IFERROR(_xlfn.SUMIFS('Total Cases'!F2:F1312,'Total Cases'!A2:A1312,H$3,'Total Cases'!B2:B1312,$A7,'Total Cases'!C2:C1312,"Cordillera Administrative Region"),0)} -> 14413.527 | I7: {=_xlfn.IFERROR(_xlfn.SUMIFS('Total Cases'!F2:F1312,'Total Cases'!A2:A1312,I$3,'Total Cases'!B2:B1312,$A7,'Total Cases'!C2:C1312,"Cordillera Administrative Region"),0)} -> 918.75231
A8: May | B8: {=_xlfn.IFERROR(_xlfn.SUMIFS('Total Cases'!F2:F1312,'Total Cases'!A2:A1312,B$3,'Total Cases'!B2:B1312,$A8,'Total Cases'!C2:C1312,"Cordillera Administrative Region"),0)} -> 436.8075 | C8: {=_xlfn.IFERROR(_xlfn.SUMIFS('Total Cases'!F2:F1312,'Total Cases'!A2:A1312,C$3,'Total Cases'!B2:B1312,$A8,'Total Cases'!C2:C1312,"Cordillera Administrative Region"),0)} -> 162.56901 | D8: {=_xlfn.IFERROR(_xlfn.SUMIFS('Total Cases'!F2:F1312,'Total Cases'!A2:A1312,D$3,'Total Cases'!B2:B1312,$A8,'Total Cases'!C2:C1312,"Cordillera Administrative Region"),0)} -> 62.583999 | E8: {=_xlfn.IFERROR(_xlfn.SUMIFS('Total Cases'!F2:F1312,'Total Cases'!A2:A1312,E$3,'Total Cases'!B2:B1312,$A8,'Total Cases'!C2:C1312,"Cordillera Administrative Region"),0)} -> 0 | F8: {=_xlfn.IFERROR(_xlfn.SUMIFS('Total Cases'!F2:F1312,'Total Cases'!A2:A1312,F$3,'Total Cases'!B2:B1312,$A8,'Total Cases'!C2:C1312,"Cordillera Administrative Region"),0)} -> 65.251689 | G8: {=_xlfn.IFERROR(_xlfn.SUMIFS('Total Cases'!F2:F1312,'Total Cases'!A2:A1312,G$3,'Total Cases'!B2:B1312,$A8,'Total Cases'!C2:C1312,"Cordillera Administrative Region"),0)} -> 139.57352 | H8: {=_xlfn.IFERROR(_xlfn.SUMIFS('Total Cases'!F2:F1312,'Total Cases'!A2:A1312,H$3,'Total Cases'!B2:B1312,$A8,'Total Cases'!C2:C1312,"Cordillera Administrative Region"),0)} -> 919.39256 | I8: {=_xlfn.IFERROR(_xlfn.SUMIFS('Total Cases'!F2:F1312,'Total Cases'!A2:A1312,I$3,'Total Cases'!B2:B1312,$A8,'Total Cases'!C2:C1312,"Cordillera Administrative Region"),0)} -> 0
A9: June | B9: {=_xlfn.IFERROR(_xlfn.SUMIFS('Total Cases'!F2:F1312,'Total Cases'!A2:A1312,B$3,'Total Cases'!B2:B1312,$A9,'Total Cases'!C2:C1312,"Cordillera Administrative Region"),0)} -> 348.08014 | C9: {=_xlfn.IFERROR(_xlfn.SUMIFS('Total Cases'!F2:F1312,'Total Cases'!A2:A1312,C$3,'Total Cases'!B2:B1312,$A9,'Total Cases'!C2:C1312,"Cordillera Administrative Region"),0)} -> 102.6527 | D9: {=_xlfn.IFERROR(_xlfn.SUMIFS('Total Cases'!F2:F1312,'Total Cases'!A2:A1312,D$3,'Total Cases'!B2:B1312,$A9,'Total Cases'!C2:C1312,"Cordillera Administrative Region"),0)} -> 158.14064 | E9: {=_xlfn.IFERROR(_xlfn.SUMIFS('Total Cases'!F2:F1312,'Total Cases'!A2:A1312,E$3,'Total Cases'!B2:B1312,$A9,'Total Cases'!C2:C1312,"Cordillera Administrative Region"),0)} -> 0 | F9: {=_xlfn.IFERROR(_xlfn.SUMIFS('Total Cases'!F2:F1312,'Total Cases'!A2:A1312,F$3,'Total Cases'!B2:B1312,$A9,'Total Cases'!C2:C1312,"Cordillera Administrative Region"),0)} -> 78.003245 | G9: {=_xlfn.IFERROR(_xlfn.SUMIFS('Total Cases'!F2:F1312,'Total Cases'!A2:A1312,G$3,'Total Cases'!B2:B1312,$A9,'Total Cases'!C2:C1312,"Cordillera Administrative Region"),0)} -> 227.55393 | H9: {=_xlfn.IFERROR(_xlfn.SUMIFS('Total Cases'!F2:F1312,'Total Cases'!A2:A1312,H$3,'Total Cases'!B2:B1312,$A9,'Total Cases'!C2:C1312,"Cordillera Administrative Region"),0)} -> 951.77831 | I9: {=_xlfn.IFERROR(_xlfn.SUMIFS('Total Cases'!F2:F1312,'Total Cases'!A2:A1312,I$3,'Total Cases'!B2:B1312,$A9,'Total Cases'!C2:C1312,"Cordillera Administrative Region"),0)} -> 0
A10: July | B10: {=_xlfn.IFERROR(_xlfn.SUMIFS('Total Cases'!F2:F1312,'Total Cases'!A2:A1312,B$3,'Total Cases'!B2:B1312,$A10,'Total Cases'!C2:C1312,"Cordillera Administrative Region"),0)} -> 391.88361 | C10: {=_xlfn.IFERROR(_xlfn.SUMIFS('Total Cases'!F2:F1312,'Total Cases'!A2:A1312,C$3,'Total Cases'!B2:B1312,$A10,'Total Cases'!C2:C1312,"Cordillera Administrative Region"),0)} -> 180.38917 | D10: {=_xlfn.IFERROR(_xlfn.SUMIFS('Total Cases'!F2:F1312,'Total Cases'!A2:A1312,D$3,'Total Cases'!B2:B1312,$A10,'Total Cases'!C2:C1312,"Cordillera Administrative Region"),0)} -> 145.28238 | E10: {=_xlfn.IFERROR(_xlfn.SUMIFS('Total Cases'!F2:F1312,'Total Cases'!A2:A1312,E$3,'Total Cases'!B2:B1312,$A10,'Total Cases'!C2:C1312,"Cordillera Administrative Region"),0)} -> 0 | F10: {=_xlfn.IFERROR(_xlfn.SUMIFS('Total Cases'!F2:F1312,'Total Cases'!A2:A1312,F$3,'Total Cases'!B2:B1312,$A10,'Total Cases'!C2:C1312,"Cordillera Administrative Region"),0)} -> 0 | G10: {=_xlfn.IFERROR(_xlfn.SUMIFS('Total Cases'!F2:F1312,'Total Cases'!A2:A1312,G$3,'Total Cases'!B2:B1312,$A10,'Total Cases'!C2:C1312,"Cordillera Administrative Region"),0)} -> 206.95936 | H10: {=_xlfn.IFERROR(_xlfn.SUMIFS('Total Cases'!F2:F1312,'Total Cases'!A2:A1312,H$3,'Total Cases'!B2:B1312,$A10,'Total Cases'!C2:C1312,"Cordillera Administrative Region"),0)} -> 735.85551 | I10: {=_xlfn.IFERROR(_xlfn.SUMIFS('Total Cases'!F2:F1312,'Total Cases'!A2:A1312,I$3,'Total Cases'!B2:B1312,$A10,'Total Cases'!C2:C1312,"Cordillera Administrative Region"),0)} -> 95.396581
A11: August | B11: {=_xlfn.IFERROR(_xlfn.SUMIFS('Total Cases'!F2:F1312,'Total Cases'!A2:A1312,B$3,'Total Cases'!B2:B1312,$A11,'Total Cases'!C2:C1312,"Cordillera Administrative Region"),0)} -> 537.21934 | C11: {=_xlfn.IFERROR(_xlfn.SUMIFS('Total Cases'!F2:F1312,'Total Cases'!A2:A1312,C$3,'Total Cases'!B2:B1312,$A11,'Total Cases'!C2:C1312,"Cordillera Administrative Region"),0)} -> 288.59066 | D11: {=_xlfn.IFERROR(_xlfn.SUMIFS('Total Cases'!F2:F1312,'Total Cases'!A2:A1312,D$3,'Total Cases'!B2:B1312,$A11,'Total Cases'!C2:C1312,"Cordillera Administrative Region"),0)} -> 88.727357 | E11: {=_xlfn.IFERROR(_xlfn.SUMIFS('Total Cases'!F2:F1312,'Total Cases'!A2:A1312,E$3,'Total Cases'!B2:B1312,$A11,'Total Cases'!C2:C1312,"Cordillera Administrative Region"),0)} -> 0 | F11: {=_xlfn.IFERROR(_xlfn.SUMIFS('Total Cases'!F2:F1312,'Total Cases'!A2:A1312,F$3,'Total Cases'!B2:B1312,$A11,'Total Cases'!C2:C1312,"Cordillera Administrative Region"),0)} -> 0 | G11: {=_xlfn.IFERROR(_xlfn.SUMIFS('Total Cases'!F2:F1312,'Total Cases'!A2:A1312,G$3,'Total Cases'!B2:B1312,$A11,'Total Cases'!C2:C1312,"Cordillera Administrative Region"),0)} -> 220.45787 | H11: {=_xlfn.IFERROR(_xlfn.SUMIFS('Total Cases'!F2:F1312,'Total Cases'!A2:A1312,H$3,'Total Cases'!B2:B1312,$A11,'Total Cases'!C2:C1312,"Cordillera Administrative Region"),0)} -> 695.52004 | I11: {=_xlfn.IFERROR(_xlfn.SUMIFS('Total Cases'!F2:F1312,'Total Cases'!A2:A1312,I$3,'Total Cases'!B2:B1312,$A11,'Total Cases'!C2:C1312,"Cordillera Administrative Region"),0)} -> 180.97606
A12: September | B12: {=_xlfn.IFERROR(_xlfn.SUMIFS('Total Cases'!F2:F1312,'Total Cases'!A2:A1312,B$3,'Total Cases'!B2:B1312,$A12,'Total Cases'!C2:C1312,"Cordillera Administrative Region"),0)} -> 288.21719 | C12: {=_xlfn.IFERROR(_xlfn.SUMIFS('Total Cases'!F2:F1312,'Total Cases'!A2:A1312,C$3,'Total Cases'!B2:B1312,$A12,'Total Cases'!C2:C1312,"Cordillera Administrative Region"),0)} -> 85.52613 | D12: {=_xlfn.IFERROR(_xlfn.SUMIFS('Total Cases'!F2:F1312,'Total Cases'!A2:A1312,D$3,'Total Cases'!B2:B1312,$A12,'Total Cases'!C2:C1312,"Cordillera Administrative Region"),0)} -> 129.64972 | E12: {=_xlfn.IFERROR(_xlfn.SUMIFS('Total Cases'!F2:F1312,'Total Cases'!A2:A1312,E$3,'Total Cases'!B2:B1312,$A12,'Total Cases'!C2:C1312,"Cordillera Administrative Region"),0)} -> 0 | F12: {=_xlfn.IFERROR(_xlfn.SUMIFS('Total Cases'!F2:F1312,'Total Cases'!A2:A1312,F$3,'Total Cases'!B2:B1312,$A12,'Total Cases'!C2:C1312,"Cordillera Administrative Region"),0)} -> 0 | G12: {=_xlfn.IFERROR(_xlfn.SUMIFS('Total Cases'!F2:F1312,'Total Cases'!A2:A1312,G$3,'Total Cases'!B2:B1312,$A12,'Total Cases'!C2:C1312,"Cordillera Administrative Region"),0)} -> 217.31 | H12: {=_xlfn.IFERROR(_xlfn.SUMIFS('Total Cases'!F2:F1312,'Total Cases'!A2:A1312,H$3,'Total Cases'!B2:B1312,$A12,'Total Cases'!C2:C1312,"Cordillera Administrative Region"),0)} -> 1348.8906 | I12: {=_xlfn.IFERROR(_xlfn.SUMIFS('Total Cases'!F2:F1312,'Total Cases'!A2:A1312,I$3,'Total Cases'!B2:B1312,$A12,'Total Cases'!C2:C1312,"Cordillera Administrative Region"),0)} -> 339.06335
A13: October | B13: {=_xlfn.IFERROR(_xlfn.SUMIFS('Total Cases'!F2:F1312,'Total Cases'!A2:A1312,B$3,'Total Cases'!B2:B1312,$A13,'Total Cases'!C2:C1312,"Cordillera Administrative Region"),0)} -> 449.98589 | C13: {=_xlfn.IFERROR(_xlfn.SUMIFS('Total Cases'!F2:F1312,'Total Cases'!A2:A1312,C$3,'Total Cases'!B2:B1312,$A13,'Total Cases'!C2:C1312,"Cordillera Administrative Region"),0)} -> 210.10724 | D13: {=_xlfn.IFERROR(_xlfn.SUMIFS('Total Cases'!F2:F1312,'Total Cases'!A2:A1312,D$3,'Total Cases'!B2:B1312,$A13,'Total Cases'!C2:C1312,"Cordillera Administrative Region"),0)} -> 171.79921 | E13: {=_xlfn.IFERROR(_xlfn.SUMIFS('Total Cases'!F2:F1312,'Total Cases'!A2:A1312,E$3,'Total Cases'!B2:B1312,$A13,'Total Cases'!C2:C1312,"Cordillera Administrative Region"),0)} -> 0 | F13: {=_xlfn.IFERROR(_xlfn.SUMIFS('Total Cases'!F2:F1312,'Total Cases'!A2:A1312,F$3,'Total Cases'!B2:B1312,$A13,'Total Cases'!C2:C1312,"Cordillera Administrative Region"),0)} -> 0 | G13: {=_xlfn.IFERROR(_xlfn.SUMIFS('Total Cases'!F2:F1312,'Total Cases'!A2:A1312,G$3,'Total Cases'!B2:B1312,$A13,'Total Cases'!C2:C1312,"Cordillera Administrative Region"),0)} -> 187.27181 | H13: {=_xlfn.IFERROR(_xlfn.SUMIFS('Total Cases'!F2:F1312,'Total Cases'!A2:A1312,H$3,'Total Cases'!B2:B1312,$A13,'Total Cases'!C2:C1312,"Cordillera Administrative Region"),0)} -> 1215.6128 | I13: {=_xlfn.IFERROR(_xlfn.SUMIFS('Total Cases'!F2:F1312,'Total Cases'!A2:A1312,I$3,'Total Cases'!B2:B1312,$A13,'Total Cases'!C2:C1312,"Cordillera Administrative Region"),0)} -> 88.033758
A14: November | B14: {=_xlfn.IFERROR(_xlfn.SUMIFS('Total Cases'!F2:F1312,'Total Cases'!A2:A1312,B$3,'Total Cases'!B2:B1312,$A14,'Total Cases'!C2:C1312,"Cordillera Administrative Region"),0)} -> 348.77374 | C14: {=_xlfn.IFERROR(_xlfn.SUMIFS('Total Cases'!F2:F1312,'Total Cases'!A2:A1312,C$3,'Total Cases'!B2:B1312,$A14,'Total Cases'!C2:C1312,"Cordillera Administrative Region"),0)} -> 158.40741 | D14: {=_xlfn.IFERROR(_xlfn.SUMIFS('Total Cases'!F2:F1312,'Total Cases'!A2:A1312,D$3,'Total Cases'!B2:B1312,$A14,'Total Cases'!C2:C1312,"Cordillera Administrative Region"),0)} -> 64.131259 | E14: {=_xlfn.IFERROR(_xlfn.SUMIFS('Total Cases'!F2:F1312,'Total Cases'!A2:A1312,E$3,'Total Cases'!B2:B1312,$A14,'Total Cases'!C2:C1312,"Cordillera Administrative Region"),0)} -> 0 | F14: {=_xlfn.IFERROR(_xlfn.SUMIFS('Total Cases'!F2:F1312,'Total Cases'!A2:A1312,F$3,'Total Cases'!B2:B1312,$A14,'Total Cases'!C2:C1312,"Cordillera Administrative Region"),0)} -> 0 | G14: {=_xlfn.IFERROR(_xlfn.SUMIFS('Total Cases'!F2:F1312,'Total Cases'!A2:A1312,G$3,'Total Cases'!B2:B1312,$A14,'Total Cases'!C2:C1312,"Cordillera Administrative Region"),0)} -> 64.344674 | H14: {=_xlfn.IFERROR(_xlfn.SUMIFS('Total Cases'!F2:F1312,'Total Cases'!A2:A1312,H$3,'Total Cases'!B2:B1312,$A14,'Total Cases'!C2:C1312,"Cordillera Administrative Region"),0)} -> 1075.0256 | I14: {=_xlfn.IFERROR(_xlfn.SUMIFS('Total Cases'!F2:F1312,'Total Cases'!A2:A1312,I$3,'Total Cases'!B2:B1312,$A14,'Total Cases'!C2:C1312,"Cordillera Administrative Region"),0)} -> 127.14209
A15: December | B15: {=_xlfn.IFERROR(_xlfn.SUMIFS('Total Cases'!F2:F1312,'Total Cases'!A2:A1312,B$3,'Total Cases'!B2:B1312,$A15,'Total Cases'!C2:C1312,"Cordillera Administrative Region"),0)} -> 348.24021 | C15: {=_xlfn.IFERROR(_xlfn.SUMIFS('Total Cases'!F2:F1312,'Total Cases'!A2:A1312,C$3,'Total Cases'!B2:B1312,$A15,'Total Cases'!C2:C1312,"Cordillera Administrative Region"),0)} -> 136.15888 | D15: {=_xlfn.IFERROR(_xlfn.SUMIFS('Total Cases'!F2:F1312,'Total Cases'!A2:A1312,D$3,'Total Cases'!B2:B1312,$A15,'Total Cases'!C2:C1312,"Cordillera Administrative Region"),0)} -> 81.844718 | E15: {=_xlfn.IFERROR(_xlfn.SUMIFS('Total Cases'!F2:F1312,'Total Cases'!A2:A1312,E$3,'Total Cases'!B2:B1312,$A15,'Total Cases'!C2:C1312,"Cordillera Administrative Region"),0)} -> 0 | F15: {=_xlfn.IFERROR(_xlfn.SUMIFS('Total Cases'!F2:F1312,'Total Cases'!A2:A1312,F$3,'Total Cases'!B2:B1312,$A15,'Total Cases'!C2:C1312,"Cordillera Administrative Region"),0)} -> 0 | G15: {=_xlfn.IFERROR(_xlfn.SUMIFS('Total Cases'!F2:F1312,'Total Cases'!A2:A1312,G$3,'Total Cases'!B2:B1312,$A15,'Total Cases'!C2:C1312,"Cordillera Administrative Region"),0)} -> 137.27931 | H15: {=_xlfn.IFERROR(_xlfn.SUMIFS('Total Cases'!F2:F1312,'Total Cases'!A2:A1312,H$3,'Total Cases'!B2:B1312,$A15,'Total Cases'!C2:C1312,"Cordillera Administrative Region"),0)} -> 867.63938 | I15: {=_xlfn.IFERROR(_xlfn.SUMIFS('Total Cases'!F2:F1312,'Total Cases'!A2:A1312,I$3,'Total Cases'!B2:B1312,$A15,'Total Cases'!C2:C1312,"Cordillera Administrative Region"),0)} -> 119.6192

Sheet Chart - Ilocos
A1: Monthly Incidence Rate (per 100k) by Disease — Ilocos
A3: Month | B3: Cardiovascular Diseases | C3: Digestive & Metabolic Disorders | D3: Genitourinary & Reproductive Health | E3: Health Services & Screening | F3: Injuries & External Causes | G3: No reported data | H3: Respiratory Diseases | I3: Skin & Soft Tissue Diseases | J3: Symptoms & Other Findings
A4: January | B4: {=_xlfn.IFERROR(_xlfn.SUMIFS('Total Cases'!F2:F1312,'Total Cases'!A2:A1312,B$3,'Total Cases'!B2:B1312,$A4,'Total Cases'!C2:C1312,"Ilocos"),0)} -> 71.783708 | C4: {=_xlfn.IFERROR(_xlfn.SUMIFS('Total Cases'!F2:F1312,'Total Cases'!A2:A1312,C$3,'Total Cases'!B2:B1312,$A4,'Total Cases'!C2:C1312,"Ilocos"),0)} -> 35.562067 | D4: {=_xlfn.IFERROR(_xlfn.SUMIFS('Total Cases'!F2:F1312,'Total Cases'!A2:A1312,D$3,'Total Cases'!B2:B1312,$A4,'Total Cases'!C2:C1312,"Ilocos"),0)} -> 9.8752983 | E4: {=_xlfn.IFERROR(_xlfn.SUMIFS('Total Cases'!F2:F1312,'Total Cases'!A2:A1312,E$3,'Total Cases'!B2:B1312,$A4,'Total Cases'!C2:C1312,"Ilocos"),0)} -> 31.916085 | F4: {=_xlfn.IFERROR(_xlfn.SUMIFS('Total Cases'!F2:F1312,'Total Cases'!A2:A1312,F$3,'Total Cases'!B2:B1312,$A4,'Total Cases'!C2:C1312,"Ilocos"),0)} -> 45.510651 | G4: {=_xlfn.IFERROR(_xlfn.SUMIFS('Total Cases'!F2:F1312,'Total Cases'!A2:A1312,G$3,'Total Cases'!B2:B1312,$A4,'Total Cases'!C2:C1312,"Ilocos"),0)} -> 0 | H4: {=_xlfn.IFERROR(_xlfn.SUMIFS('Total Cases'!F2:F1312,'Total Cases'!A2:A1312,H$3,'Total Cases'!B2:B1312,$A4,'Total Cases'!C2:C1312,"Ilocos"),0)} -> 129.20335 | I4: {=_xlfn.IFERROR(_xlfn.SUMIFS('Total Cases'!F2:F1312,'Total Cases'!A2:A1312,I$3,'Total Cases'!B2:B1312,$A4,'Total Cases'!C2:C1312,"Ilocos"),0)} -> 11.689129 | J4: {=_xlfn.IFERROR(_xlfn.SUMIFS('Total Cases'!F2:F1312,'Total Cases'!A2:A1312,J$3,'Total Cases'!B2:B1312,$A4,'Total Cases'!C2:C1312,"Ilocos"),0)} -> 0
